<?xml version="1.0" ?>
<!-- =================================================================================== -->
<!-- |    This document was autogenerated by xacro from iiwa14.urdf.xacro              | -->
<!-- |    EDITING THIS FILE BY HAND IS NOT RECOMMENDED                                 | -->
<!-- =================================================================================== -->
<!-- top level -->
<robot name="iiwa14">
  <material name="orange">
    <color rgba="1.0 0.42 0.04 1.0"/>
  </material>
  <material name="white">
    <color rgba="1.0 1.0 1.0 1.0"/>
  </material>
  <material name="silver">
    <color rgba="0.7 0.7 0.7 1.0"/>
  </material>
  <!-- fix to world -->
  <link name="world"/>
  <!--joint between {parent} and link_0-->
  <joint name="world_lbr_joint" type="fixed">
    <parent link="world"/>
    <child link="lbr_link_0"/>
  </joint>
  <link name="lbr_link_0">
    <inertial>
      <origin rpy="0 0 0" xyz="-0.0128215344957798 -7.86364415362405e-08 0.07150661827888387"/>
      <mass value="7.039242"/>
      <inertia ixx="0.031177" ixy="0.000000" ixz="0.000870" iyy="0.039634" iyz="0.000000" izz="0.043034"/>
    </inertial>
    <visual>
      <origin rpy="0 0 0" xyz="0 0 0"/>
      <geometry>
        <mesh filename="package://lbr_description/meshes/iiwa14/visual/link_0.stl"/>
      </geometry>
      <material name="silver"/>
    </visual>
    <collision>
      <origin rpy="0 0 0" xyz="0 0 0"/>
      <geometry>
        <mesh filename="package://lbr_description/meshes/iiwa14/collision/link_0.stl"/>
      </geometry>
    </collision>
  </link>
  <joint name="lbr_joint_0" type="revolute">
    <origin rpy="0 0 0" xyz="0.0 0.0 0.1475"/>
    <parent link="lbr_link_0"/>
    <child link="lbr_link_1"/>
    <axis xyz="0.0 0.0 1.0"/>
    <limit effort="200" lower="-2.9670597283903604" upper="2.9670597283903604" velocity="1.4835298641951802"/>
    <dynamics damping="10.0" friction="0.1"/>
  </joint>
  <link name="lbr_link_1">
    <inertial>
      <origin rpy="0 0 0" xyz="9.307232415315581e-08 -0.03379543155079102 0.13240370669453902"/>
      <mass value="5.281174"/>
      <inertia ixx="0.042394" ixy="-0.000000" ixz="-0.000000" iyy="0.042770" iyz="0.006331" izz="0.015845"/>
    </inertial>
    <visual>
      <origin rpy="0 0 0" xyz="-0.0 0.0 -0.1475"/>
      <geometry>
        <mesh filename="package://lbr_description/meshes/iiwa14/visual/link_1.stl"/>
      </geometry>
      <material name="orange"/>
    </visual>
    <collision>
      <origin rpy="0 0 0" xyz="-0.0 0.0 -0.1475"/>
      <geometry>
        <mesh filename="package://lbr_description/meshes/iiwa14/collision/link_1.stl"/>
      </geometry>
    </collision>
  </link>
  <joint name="lbr_joint_1" type="revolute">
    <origin rpy="0 0 0" xyz="0.0 -0.01 0.2125"/>
    <parent link="lbr_link_1"/>
    <child link="lbr_link_2"/>
    <axis xyz="0.0 1.0 0.0"/>
    <limit effort="200" lower="-2.0943951023931953" upper="2.0943951023931953" velocity="1.4835298641951802"/>
    <dynamics damping="10.0" friction="0.1"/>
  </joint>
  <link name="lbr_link_2">
    <inertial>
      <origin rpy="0 0 0" xyz="0.00015188022518878674 0.051987109728758904 0.05880129877994178"/>
      <mass value="5.079432"/>
      <inertia ixx="0.039326" ixy="-0.000029" ixz="0.000042" iyy="0.039101" iyz="0.006282" izz="0.014161"/>
    </inertial>
    <visual>
      <origin rpy="0 0 0" xyz="-0.0 0.01 -0.36"/>
      <geometry>
        <mesh filename="package://lbr_description/meshes/iiwa14/visual/link_2.stl"/>
      </geometry>
      <material name="orange"/>
    </visual>
    <collision>
      <origin rpy="0 0 0" xyz="-0.0 0.01 -0.36"/>
      <geometry>
        <mesh filename="package://lbr_description/meshes/iiwa14/collision/link_2.stl"/>
      </geometry>
    </collision>
  </link>
  <joint name="lbr_joint_2" type="revolute">
    <origin rpy="0 0 0" xyz="0.0 0.01 0.1945"/>
    <parent link="lbr_link_2"/>
    <child link="lbr_link_3"/>
    <axis xyz="0.0 0.0 1.0"/>
    <limit effort="200" lower="-2.9670597283903604" upper="2.9670597283903604" velocity="1.7453292519943295"/>
    <dynamics damping="10.0" friction="0.1"/>
  </joint>
  <link name="lbr_link_3">
    <inertial>
      <origin rpy="0 0 0" xyz="-5.974614313346012e-09 0.029563618732667742 0.13650341869763982"/>
      <mass value="4.0811177"/>
      <inertia ixx="0.032236" ixy="-0.000000" ixz="0.000000" iyy="0.030602" iyz="-0.006265" izz="0.009779"/>
    </inertial>
    <visual>
      <origin rpy="0 0 0" xyz="-0.0 0.0 -0.5545"/>
      <geometry>
        <mesh filename="package://lbr_description/meshes/iiwa14/visual/link_3.stl"/>
      </geometry>
      <material name="orange"/>
    </visual>
    <collision>
      <origin rpy="0 0 0" xyz="-0.0 0.0 -0.5545"/>
      <geometry>
        <mesh filename="package://lbr_description/meshes/iiwa14/collision/link_3.stl"/>
      </geometry>
    </collision>
  </link>
  <joint name="lbr_joint_3" type="revolute">
    <origin rpy="0 0 0" xyz="-0.0 0.0105 0.2255"/>
    <parent link="lbr_link_3"/>
    <child link="lbr_link_4"/>
    <axis xyz="0.0 -1.0 0.0"/>
    <limit effort="200" lower="-2.0943951023931953" upper="2.0943951023931953" velocity="1.3089969389957472"/>
    <dynamics damping="10.0" friction="0.1"/>
  </joint>
  <link name="lbr_link_4">
    <inertial>
      <origin rpy="0 0 0" xyz="-2.09625967727708e-08 -0.04476439079596513 0.06741903952954653"/>
      <mass value="3.521230"/>
      <inertia ixx="0.022114" ixy="-0.000000" ixz="-0.000000" iyy="0.021074" iyz="-0.003660" izz="0.007890"/>
    </inertial>
    <visual>
      <origin rpy="0 0 0" xyz="0.0 -0.0105 -0.78"/>
      <geometry>
        <mesh filename="package://lbr_description/meshes/iiwa14/visual/link_4.stl"/>
      </geometry>
      <material name="orange"/>
    </visual>
    <collision>
      <origin rpy="0 0 0" xyz="0.0 -0.0105 -0.78"/>
      <geometry>
        <mesh filename="package://lbr_description/meshes/iiwa14/collision/link_4.stl"/>
      </geometry>
    </collision>
  </link>
  <joint name="lbr_joint_4" type="revolute">
    <origin rpy="0 0 0" xyz="0.0 -0.0105 0.1745"/>
    <parent link="lbr_link_4"/>
    <child link="lbr_link_5"/>
    <axis xyz="0.0 0.0 1.0"/>
    <limit effort="200" lower="-2.9670597283903604" upper="2.9670597283903604" velocity="2.2689280275926285"/>
    <dynamics damping="10.0" friction="0.1"/>
  </joint>
  <link name="lbr_link_5">
    <inertial>
      <origin rpy="0 0 0" xyz="-0.00012008657208039079 -0.021390023245727908 0.0854754261653966"/>
      <mass value="2.176916"/>
      <inertia ixx="0.012955" ixy="0.000002" ixz="-0.000001" iyy="0.011185" iyz="0.003972" izz="0.005744"/>
    </inertial>
    <visual>
      <origin rpy="0 0 0" xyz="-0.0 0.0 -0.9545"/>
      <geometry>
        <mesh filename="package://lbr_description/meshes/iiwa14/visual/link_5.stl"/>
      </geometry>
      <material name="orange"/>
    </visual>
    <collision>
      <origin rpy="0 0 0" xyz="-0.0 0.0 -0.9545"/>
      <geometry>
        <mesh filename="package://lbr_description/meshes/iiwa14/collision/link_5.stl"/>
      </geometry>
    </collision>
  </link>
  <joint name="lbr_joint_5" type="revolute">
    <origin rpy="0 0 0" xyz="-0.0 -0.0707 0.2255"/>
    <parent link="lbr_link_5"/>
    <child link="lbr_link_6"/>
    <axis xyz="0.0 1.0 0.0"/>
    <limit effort="200" lower="-2.0943951023931953" upper="2.0943951023931953" velocity="2.356194490192345"/>
    <dynamics damping="10.0" friction="0.1"/>
  </joint>
  <link name="lbr_link_6">
    <inertial>
      <origin rpy="0 0 0" xyz="-6.000032555678588e-08 0.07103825551434698 0.000565530522845803"/>
      <mass value="2.324906"/>
      <inertia ixx="0.006292" ixy="-0.000000" ixz="-0.000000" iyy="0.006023" iyz="0.000314" izz="0.004585"/>
    </inertial>
    <visual>
      <origin rpy="0 0 0" xyz="0.0 0.0707 -1.18"/>
      <geometry>
        <mesh filename="package://lbr_description/meshes/iiwa14/visual/link_6.stl"/>
      </geometry>
      <material name="orange"/>
    </visual>
    <collision>
      <origin rpy="0 0 0" xyz="0.0 0.0707 -1.18"/>
      <geometry>
        <mesh filename="package://lbr_description/meshes/iiwa14/collision/link_6.stl"/>
      </geometry>
    </collision>
  </link>
  <joint name="lbr_joint_6" type="revolute">
    <origin rpy="0 0 0" xyz="0.0 0.0707 0.0711"/>
    <parent link="lbr_link_6"/>
    <child link="lbr_link_7"/>
    <axis xyz="0.0 0.0 1.0"/>
    <limit effort="200" lower="-3.0543261909900763" upper="3.0543261909900763" velocity="2.356194490192345"/>
    <dynamics damping="10.0" friction="0.1"/>
  </joint>
  <link name="lbr_link_7">
    <inertial>
      <origin rpy="0 0 0" xyz="3.963019849314055e-06 -1.5392768444664745e-08 0.027186686478491096"/>
      <mass value="0.395984"/>
      <inertia ixx="0.000281" ixy="-0.000000" ixz="-0.000000" iyy="0.000277" iyz="0.000000" izz="0.000430"/>
    </inertial>
    <visual>
      <origin rpy="0 0 0" xyz="0.0 0.0 -1.2511"/>
      <geometry>
        <mesh filename="package://lbr_description/meshes/iiwa14/visual/link_7.stl"/>
      </geometry>
      <material name="silver"/>
    </visual>
    <collision>
      <origin rpy="0 0 0" xyz="0.0 0.0 -1.2511"/>
      <geometry>
        <mesh filename="package://lbr_description/meshes/iiwa14/collision/link_7.stl"/>
      </geometry>
    </collision>
  </link>
  <joint name="lbr_joint_ee" type="fixed">
    <parent link="lbr_link_7"/>
    <child link="lbr_link_ee"/>
    <origin rpy="0 0 0" xyz="0 0 0.035"/>
  </joint>
  <link name="lbr_link_ee">
        </link>
  <!-- ros_control-plugin -->
  <gazebo>
    <plugin filename="libgazebo_ros2_control.so" name="gazebo_ros2_control">
      <parameters>/home/pingpongproject/code/ping-pong-robot/lbr_fri_ros2_stack_ws_foxy/install/lbr_bringup/share/lbr_bringup/config/lbr_controllers.yml</parameters>
      <robotNamespace>/lbr</robotNamespace>
    </plugin>
  </gazebo>
  <!-- link 0 -->
  <gazebo reference="lbr_link_0">
    <mu1>0.2</mu1>
    <mu2>0.2</mu2>
    <material>Gazebo/Grey</material>
  </gazebo>
  <!-- link 1 -->
  <gazebo reference="lbr_link_1">
    <mu1>0.2</mu1>
    <mu2>0.2</mu2>
    <material>Gazebo/Orange</material>
  </gazebo>
  <!-- link 2 -->
  <gazebo reference="lbr_link_2">
    <mu1>0.2</mu1>
    <mu2>0.2</mu2>
    <material>Gazebo/Orange</material>
  </gazebo>
  <!-- link 3 -->
  <gazebo reference="lbr_link_3">
    <mu1>0.2</mu1>
    <mu2>0.2</mu2>
    <material>Gazebo/Orange</material>
  </gazebo>
  <!-- link 4 -->
  <gazebo reference="lbr_link_4">
    <mu1>0.2</mu1>
    <mu2>0.2</mu2>
    <material>Gazebo/Orange</material>
  </gazebo>
  <!-- link 5 -->
  <gazebo reference="lbr_link_5">
    <mu1>0.2</mu1>
    <mu2>0.2</mu2>
    <material>Gazebo/Orange</material>
  </gazebo>
  <!-- link 6 -->
  <gazebo reference="lbr_link_6">
    <mu1>0.2</mu1>
    <mu2>0.2</mu2>
    <material>Gazebo/Orange</material>
  </gazebo>
  <!-- link 7 -->
  <gazebo reference="lbr_link_7">
    <mu1>0.2</mu1>
    <mu2>0.2</mu2>
    <material>Gazebo/Grey</material>
  </gazebo>
  <!-- arg for control mode -->
  <ros2_control name="lbr_hardware_interface" type="system">
    <hardware>
      <plugin>gazebo_ros2_control/GazeboSystem</plugin>
    </hardware>
    <!-- define joints and command/state interfaces for each joint -->
    <joint name="lbr_joint_0">
      <command_interface name="position">
        <!-- better to use radians as min max first -->
        <param name="min">-2.9670597283903604</param>
        <param name="max"> 2.9670597283903604</param>
      </command_interface>
      <command_interface name="effort">
        <param name="min">-200</param>
        <param name="max"> 200</param>
      </command_interface>
      <state_interface name="position"/>
      <state_interface name="velocity"/>
      <state_interface name="effort"/>
    </joint>
    <joint name="lbr_joint_1">
      <command_interface name="position">
        <param name="min">-2.0943951023931953</param>
        <param name="max"> 2.0943951023931953</param>
      </command_interface>
      <command_interface name="effort">
        <param name="min">-200</param>
        <param name="max"> 200</param>
      </command_interface>
      <state_interface name="position"/>
      <state_interface name="velocity"/>
      <state_interface name="effort"/>
    </joint>
    <joint name="lbr_joint_2">
      <command_interface name="position">
        <param name="min">-2.9670597283903604</param>
        <param name="max"> 2.9670597283903604</param>
      </command_interface>
      <command_interface name="effort">
        <param name="min">-200</param>
        <param name="max"> 200</param>
      </command_interface>
      <state_interface name="position"/>
      <state_interface name="velocity"/>
      <state_interface name="effort"/>
    </joint>
    <joint name="lbr_joint_3">
      <command_interface name="position">
        <param name="min">-2.0943951023931953</param>
        <param name="max"> 2.0943951023931953</param>
      </command_interface>
      <command_interface name="effort">
        <param name="min">-200</param>
        <param name="max"> 200</param>
      </command_interface>
      <state_interface name="position"/>
      <state_interface name="velocity"/>
      <state_interface name="effort"/>
    </joint>
    <joint name="lbr_joint_4">
      <command_interface name="position">
        <param name="min">-2.9670597283903604</param>
        <param name="max"> 2.9670597283903604</param>
      </command_interface>
      <command_interface name="effort">
        <param name="min">-200</param>
        <param name="max"> 200</param>
      </command_interface>
      <state_interface name="position"/>
      <state_interface name="velocity"/>
      <state_interface name="effort"/>
    </joint>
    <joint name="lbr_joint_5">
      <command_interface name="position">
        <param name="min">-2.0943951023931953</param>
        <param name="max"> 2.0943951023931953</param>
      </command_interface>
      <command_interface name="effort">
        <param name="min">-200</param>
        <param name="max"> 200</param>
      </command_interface>
      <state_interface name="position"/>
      <state_interface name="velocity"/>
      <state_interface name="effort"/>
    </joint>
    <joint name="lbr_joint_6">
      <command_interface name="position">
        <param name="min">-3.0543261909900763</param>
        <param name="max"> 3.0543261909900763</param>
      </command_interface>
      <command_interface name="effort">
        <param name="min">-200</param>
        <param name="max"> 200</param>
      </command_interface>
      <state_interface name="position"/>
      <state_interface name="velocity"/>
      <state_interface name="effort"/>
    </joint>
  </ros2_control>
</robot>
